Workbook

Sheet Ventas_odoo Interface
A1: Número | B1: Número_replica | C1: (PE) Document Number | D1: Número de Documento | E1: BUSQUEDA | F1: VAOPE Codigo Evento | G1: Evento | H1: Nombre del contacto a mostrar en la factura | I1: Fecha de factura | J1: Fecha | K1: Fecha de vencimiento | L1: Origen | M1: Referencia de pago | N1: Referencia | O1: Actividades | P1: Empresa | Q1: Importe sin impuestos firmado | R1: Impuesto firmado | S1: Total firmado | T1: Total en divisa firmado | U1: Importe pendiente firmado | V1: Moneda | W1: Por revisar | X1: Estado de pago | Y1: Facturación electrónica | Z1: Nivel de bloqueo de EDI | AA1: Mensaje de error de EDI | AB1: Estado | AC1: Tipo de gasto | AD1: nro_productos | AE1: Nombre Producto | AF1: Distribucion_analitica | AG1: %distribucion | AH1: Nombre Cuenta | AI1: Valor Unitario | AJ1: Precio_Unitario | AK1: Descuento | AL1: Tipo_cambio | AM1: Fecha Evento | AN1: FechaEvento_fechaFactura | AO1: busque
A2: FXP/2025/10/0117 | B2: FXP/2025/10/0117 | C2: E001-00000068 | D2: 02-E001-00000068 | E2: =+IF(C2="",SUBSTITUTE(SUBSTITUTE(SUBSTITUTE(B2,CHAR(160)," ")," -","-"),"- ","-"),SUBSTITUTE(SUBSTITUTE(SUBSTITUTE(C2,CHAR(160)," ")," -","-"),"- ","-")) -> E001-00000068 | F2: 0 | H2: VENTURA SABINO MIGUEL ANGEL | I2: 45944 | J2: 45944 | K2: 45944 | O2: PENDIENTE DE PAGO | P2: COLABORATIVA S.A.C. | Q2: -2170 | S2: -2170 | T2: -2170 | V2: PEN | W2: FALSE | X2: Pagado | AB2: Registrado | AN2: =+IF(AM2<>"",AM2,I2) -> 45944 | AO2: =+VLOOKUP(D2,validaciones_json!$AS:$AS,1,0) -> #N/A
A3: FXP/2025/10/0116 | B3: FXP/2025/10/0116 | C3: F002-00001584 | D3: 01-F002-00001584 | E3: =+IF(C3="",SUBSTITUTE(SUBSTITUTE(SUBSTITUTE(B3,CHAR(160)," ")," -","-"),"- ","-"),SUBSTITUTE(SUBSTITUTE(SUBSTITUTE(C3,CHAR(160)," ")," -","-"),"- ","-")) -> F002-00001584 | F3: 0 | H3: PRAGMATIC S.A.C. | I3: 45943 | J3: 45943 | K3: 45944 | L3: P00289 | N3: F002-00001584 | P3: COLABORATIVA S.A.C. | Q3: -450 | R3: -81 | S3: -531 | T3: -531 | V3: PEN | W3: FALSE | X3: Pagado | AB3: Registrado | AN3: =+IF(AM3<>"",AM3,I3) -> 45943 | AO3: =+VLOOKUP(D3,validaciones_json!$AS:$AS,1,0) -> #N/A
A4: FXP/2025/10/0113 | B4: FXP/2025/10/0113 | C4: E001-00000005 | D4: T-E001-00000005 | E4: =+IF(C4="",SUBSTITUTE(SUBSTITUTE(SUBSTITUTE(B4,CHAR(160)," ")," -","-"),"- ","-"),SUBSTITUTE(SUBSTITUTE(SUBSTITUTE(C4,CHAR(160)," ")," -","-"),"- ","-")) -> E001-00000005 | F4: 0 | H4: GUTIERREZ PETIT MARIA ANGEL | I4: 45943 | J4: 45943 | K4: 45943 | N4: E001-5 | P4: COLABORATIVA S.A.C. | Q4: -3550 | S4: -3550 | T4: -3550 | V4: PEN | W4: FALSE | X4: Pagado | AB4: Registrado | AN4: =+IF(AM4<>"",AM4,I4) -> 45943 | AO4: =+VLOOKUP(D4,validaciones_json!$AS:$AS,1,0) -> #N/A
A5: FXP/2025/10/0109 | B5: FXP/2025/10/0109 | C5: E001-00000039 | D5: 02-E001-00000039 | E5: =+IF(C5="",SUBSTITUTE(SUBSTITUTE(SUBSTITUTE(B5,CHAR(160)," ")," -","-"),"- ","-"),SUBSTITUTE(SUBSTITUTE(SUBSTITUTE(C5,CHAR(160)," ")," -","-"),"- ","-")) -> E001-00000039 | F5: 0 | H5: CARMEN CRUZ MILAGROS ZONALI | I5: 45942 | J5: 45943 | K5: 45942 | L5: P00286 | N5: E001-39 | P5: COLABORATIVA S.A.C. | Q5: -1640 | S5: -1640 | T5: -1640 | V5: PEN | W5: FALSE | X5: Pagado | AB5: Registrado | AN5: =+IF(AM5<>"",AM5,I5) -> 45942 | AO5: =+VLOOKUP(D5,validaciones_json!$AS:$AS,1,0) -> #N/A
A6: FXP/2025/10/0111 | B6: FXP/2025/10/0111 | C6: F052-01689541 | D6: 01-F052-01689541 | E6: =+IF(C6="",SUBSTITUTE(SUBSTITUTE(SUBSTITUTE(B6,CHAR(160)," ")," -","-"),"- ","-"),SUBSTITUTE(SUBSTITUTE(SUBSTITUTE(C6,CHAR(160)," ")," -","-"),"- ","-")) -> F052-01689541 | F6: 0 | H6: MAPFRE PERU S.A. | I6: 45941 | J6: 45941 | K6: 45941 | L6: P00285 | N6: F052-01689541 | P6: COLABORATIVA S.A.C. | Q6: -225 | R6: -40.5 | S6: -265.5 | T6: -265.5 | V6: PEN | W6: FALSE | X6: Pagado | AB6: Registrado | AN6: =+IF(AM6<>"",AM6,I6) -> 45941 | AO6: =+VLOOKUP(D6,validaciones_json!$AS:$AS,1,0) -> #N/A
A7: FXP/2025/10/0112 | B7: FXP/2025/10/0112 | C7: E001- 20 | D7: T-E001- 20 | E7: =+IF(C7="",SUBSTITUTE(SUBSTITUTE(SUBSTITUTE(B7,CHAR(160)," ")," -","-"),"- ","-"),SUBSTITUTE(SUBSTITUTE(SUBSTITUTE(C7,CHAR(160)," ")," -","-"),"- ","-")) -> E001-20 | F7: 0 | H7: VARGAS HUARCAYA DANIELA RUBI | I7: 45940 | J7: 45940 | K7: 45940 | N7: E001- 20 | P7: COLABORATIVA S.A.C. | Q7: -5400 | S7: -5400 | T7: -5400 | V7: PEN | W7: FALSE | X7: Pagado | AB7: Registrado | AN7: =+IF(AM7<>"",AM7,I7) -> 45940 | AO7: =+VLOOKUP(D7,validaciones_json!$AS:$AS,1,0) -> #N/A
A8: FXP/2025/10/0110 | B8: FXP/2025/10/0110 | C8: F250-00000900 | D8: 01-F250-00000900 | E8: =+IF(C8="",SUBSTITUTE(SUBSTITUTE(SUBSTITUTE(B8,CHAR(160)," ")," -","-"),"- ","-"),SUBSTITUTE(SUBSTITUTE(SUBSTITUTE(C8,CHAR(160)," ")," -","-"),"- ","-")) -> F250-00000900 | F8: 0 | H8: DOLCE CAPRICCIO SAC | I8: 45940 | J8: 45940 | K8: 45943 | L8: P00284 | P8: COLABORATIVA S.A.C. | Q8: -101.69 | R8: -18.31 | S8: -120 | T8: -120 | V8: PEN | W8: FALSE | X8: Pagado | AB8: Registrado | AN8: =+IF(AM8<>"",AM8,I8) -> 45940 | AO8: =+VLOOKUP(D8,validaciones_json!$AS:$AS,1,0) -> #N/A
A9: FXP/2025/10/0108 | B9: FXP/2025/10/0108 | C9: E001- 18 | D9: T-E001- 18 | E9: =+IF(C9="",SUBSTITUTE(SUBSTITUTE(SUBSTITUTE(B9,CHAR(160)," ")," -","-"),"- ","-"),SUBSTITUTE(SUBSTITUTE(SUBSTITUTE(C9,CHAR(160)," ")," -","-"),"- ","-")) -> E001-18 | F9: 0 | H9: GALVAN VARGAS DAYANA LIZBETH | I9: 45940 | J9: 45940 | K9: 45940 | N9: E001- 18 | P9: COLABORATIVA S.A.C. | Q9: -7000 | S9: -7000 | T9: -7000 | V9: PEN | W9: FALSE | X9: Pagado | AB9: Registrado | AN9: =+IF(AM9<>"",AM9,I9) -> 45940 | AO9: =+VLOOKUP(D9,validaciones_json!$AS:$AS,1,0) -> #N/A
A10: FXP/2025/10/0106 | B10: FXP/2025/10/0106 | C10: E001-00000057 | D10: 02-E001-00000057 | E10: =+IF(C10="",SUBSTITUTE(SUBSTITUTE(SUBSTITUTE(B10,CHAR(160)," ")," -","-"),"- ","-"),SUBSTITUTE(SUBSTITUTE(SUBSTITUTE(C10,CHAR(160)," ")," -","-"),"- ","-")) -> E001-00000057 | F10: 0 | H10: SOLANO CALDERON JUAN ALONSO | I10: 45940 | J10: 45940 | K10: 45940 | L10: P00283 | P10: COLABORATIVA S.A.C. | Q10: -338.98 | R10: -61.02 | S10: -400 | T10: -400 | V10: PEN | W10: FALSE | X10: Pagado | AB10: Registrado | AN10: =+IF(AM10<>"",AM10,I10) -> 45940 | AO10: =+VLOOKUP(D10,validaciones_json!$AS:$AS,1,0) -> #N/A
A11: FXP/2025/10/0105 | B11: FXP/2025/10/0105 | C11: E001-00000026 | D11: 02-E001-00000026 | E11: =+IF(C11="",SUBSTITUTE(SUBSTITUTE(SUBSTITUTE(B11,CHAR(160)," ")," -","-"),"- ","-"),SUBSTITUTE(SUBSTITUTE(SUBSTITUTE(C11,CHAR(160)," ")," -","-"),"- ","-")) -> E001-00000026 | F11: 0 | H11: ESPINO MORI LEANDRO JOAQUIN | I11: 45940 | J11: 45940 | K11: 45940 | L11: P00282 | P11: COLABORATIVA S.A.C. | Q11: -296.61 | R11: -53.39 | S11: -350 | T11: -350 | V11: PEN | W11: FALSE | X11: Pagado | AB11: Registrado | AN11: =+IF(AM11<>"",AM11,I11) -> 45940 | AO11: =+VLOOKUP(D11,validaciones_json!$AS:$AS,1,0) -> #N/A
A12: FXP/2025/10/0102 | B12: FXP/2025/10/0102 | C12: F030-00008004 | D12: 01-F030-00008004 | E12: =+IF(C12="",SUBSTITUTE(SUBSTITUTE(SUBSTITUTE(B12,CHAR(160)," ")," -","-"),"- ","-"),SUBSTITUTE(SUBSTITUTE(SUBSTITUTE(C12,CHAR(160)," ")," -","-"),"- ","-")) -> F030-00008004 | F12: 0 | H12: PANIFICADORA LA NUEZ SAC | I12: 45931 | J12: 45940 | K12: 45931 | N12: F030-00008004 | P12: COLABORATIVA S.A.C. | Q12: -71.7 | S12: -71.7 | T12: -71.7 | V12: PEN | W12: FALSE | X12: Pagado | AB12: Registrado | AN12: =+IF(AM12<>"",AM12,I12) -> 45931 | AO12: =+VLOOKUP(D12,validaciones_json!$AS:$AS,1,0) -> #N/A
A13: FXP/2025/10/0101 | B13: FXP/2025/10/0101 | C13: F301-00040284 | D13: 01-F301-00040284 | E13: =+IF(C13="",SUBSTITUTE(SUBSTITUTE(SUBSTITUTE(B13,CHAR(160)," ")," -","-"),"- ","-"),SUBSTITUTE(SUBSTITUTE(SUBSTITUTE(C13,CHAR(160)," ")," -","-"),"- ","-")) -> F301-00040284 | F13: 0 | H13: INVERSIONES SAP S.A. | I13: 45937 | J13: 45940 | K13: 45937 | N13: F301-00040284 | P13: COLABORATIVA S.A.C. | Q13: -127.8 | S13: -127.8 | T13: -127.8 | V13: PEN | W13: FALSE | X13: Pagado | AB13: Registrado | AN13: =+IF(AM13<>"",AM13,I13) -> 45937 | AO13: =+VLOOKUP(D13,validaciones_json!$AS:$AS,1,0) -> #N/A
A14: FXP/2025/10/0100 | B14: FXP/2025/10/0100 | C14: F004-00001283 | D14: 01-F004-00001283 | E14: =+IF(C14="",SUBSTITUTE(SUBSTITUTE(SUBSTITUTE(B14,CHAR(160)," ")," -","-"),"- ","-"),SUBSTITUTE(SUBSTITUTE(SUBSTITUTE(C14,CHAR(160)," ")," -","-"),"- ","-")) -> F004-00001283 | F14: 0 | H14: ORIENTAL GOURMET S.A. | I14: 45936 | J14: 45940 | K14: 45936 | N14: F004-1283 | P14: COLABORATIVA S.A.C. | Q14: -64.5 | S14: -64.5 | T14: -64.5 | V14: PEN | W14: FALSE | X14: Pagado | AB14: Registrado | AN14: =+IF(AM14<>"",AM14,I14) -> 45936 | AO14: =+VLOOKUP(D14,validaciones_json!$AS:$AS,1,0) -> #N/A
A15: FXP/2025/10/0099 | B15: FXP/2025/10/0099 | C15: F003-00001183 | D15: 01-F003-00001183 | E15: =+IF(C15="",SUBSTITUTE(SUBSTITUTE(SUBSTITUTE(B15,CHAR(160)," ")," -","-"),"- ","-"),SUBSTITUTE(SUBSTITUTE(SUBSTITUTE(C15,CHAR(160)," ")," -","-"),"- ","-")) -> F003-00001183 | F15: 0 | H15: MALBEC SAC | I15: 45939 | J15: 45940 | K15: 45939 | N15: F003-00001183 | P15: COLABORATIVA S.A.C. | Q15: -462 | S15: -462 | T15: -462 | V15: PEN | W15: FALSE | X15: Pagado | AB15: Registrado | AN15: =+IF(AM15<>"",AM15,I15) -> 45939 | AO15: =+VLOOKUP(D15,validaciones_json!$AS:$AS,1,0) -> #N/A
A16: FXP/2025/10/0107 | B16: FXP/2025/10/0107 | C16: E001-00000013 | D16: 01-E001-00000013 | E16: =+IF(C16="",SUBSTITUTE(SUBSTITUTE(SUBSTITUTE(B16,CHAR(160)," ")," -","-"),"- ","-"),SUBSTITUTE(SUBSTITUTE(SUBSTITUTE(C16,CHAR(160)," ")," -","-"),"- ","-")) -> E001-00000013 | F16: 0 | H16: KUNTUR PRO S.A.C. | I16: 45939 | J16: 45939 | K16: 45940 | P16: COLABORATIVA S.A.C. | Q16: -1000 | R16: -180 | S16: -1180 | T16: -1180 | V16: PEN | W16: FALSE | X16: Pagado | AB16: Registrado | AN16: =+IF(AM16<>"",AM16,I16) -> 45939 | AO16: =+VLOOKUP(D16,validaciones_json!$AS:$AS,1,0) -> #N/A
A17: FXP/2025/10/0096 | B17: FXP/2025/10/0096 | C17: E001-00000493 | D17: 01-E001-00000493 | E17: =+IF(C17="",SUBSTITUTE(SUBSTITUTE(SUBSTITUTE(B17,CHAR(160)," ")," -","-"),"- ","-"),SUBSTITUTE(SUBSTITUTE(SUBSTITUTE(C17,CHAR(160)," ")," -","-"),"- ","-")) -> E001-00000493 | F17: 0 | H17: EURO CARS PERU S.A.C. | I17: 45938 | J17: 45938 | K17: 45939 | L17: P00276 | N17: E001-493 | P17: COLABORATIVA S.A.C. | Q17: -110.17 | R17: -19.84 | S17: -130.01 | T17: -130.01 | V17: PEN | W17: FALSE | X17: Pagado | AB17: Registrado | AN17: =+IF(AM17<>"",AM17,I17) -> 45938 | AO17: =+VLOOKUP(D17,validaciones_json!$AS:$AS,1,0) -> #N/A
A18: FXP/2025/10/0095 | B18: FXP/2025/10/0095 | C18: E001-00000492 | D18: 01-E001-00000492 | E18: =+IF(C18="",SUBSTITUTE(SUBSTITUTE(SUBSTITUTE(B18,CHAR(160)," ")," -","-"),"- ","-"),SUBSTITUTE(SUBSTITUTE(SUBSTITUTE(C18,CHAR(160)," ")," -","-"),"- ","-")) -> E001-00000492 | F18: 0 | H18: EURO CARS PERU S.A.C. | I18: 45938 | J18: 45938 | K18: 45939 | L18: P00277 | N18: E001-492 | P18: COLABORATIVA S.A.C. | Q18: -550.85 | R18: -99.17 | S18: -650.02 | T18: -650.02 | V18: PEN | W18: FALSE | X18: Pagado | AB18: Registrado | AN18: =+IF(AM18<>"",AM18,I18) -> 45938 | AO18: =+VLOOKUP(D18,validaciones_json!$AS:$AS,1,0) -> #N/A
A19: FXP/2025/10/0094 | B19: FXP/2025/10/0094 | C19: E001-00000127 | D19: 01-E001-00000127 | E19: =+IF(C19="",SUBSTITUTE(SUBSTITUTE(SUBSTITUTE(B19,CHAR(160)," ")," -","-"),"- ","-"),SUBSTITUTE(SUBSTITUTE(SUBSTITUTE(C19,CHAR(160)," ")," -","-"),"- ","-")) -> E001-00000127 | F19: 0 | H19: MUÑOZ VERANO JOHN BRACKSON | I19: 45937 | J19: 45937 | K19: 45939 | L19: P00271 | N19: E001-127 | P19: COLABORATIVA S.A.C. | Q19: -1200 | R19: -216 | S19: -1416 | T19: -1416 | V19: PEN | W19: FALSE | X19: Pagado | AB19: Registrado | AN19: =+IF(AM19<>"",AM19,I19) -> 45937 | AO19: =+VLOOKUP(D19,validaciones_json!$AS:$AS,1,0) -> #N/A
A20: FXP/2025/10/0093 | B20: FXP/2025/10/0093 | C20: E001-00000129 | D20: 01-E001-00000129 | E20: =+IF(C20="",SUBSTITUTE(SUBSTITUTE(SUBSTITUTE(B20,CHAR(160)," ")," -","-"),"- ","-"),SUBSTITUTE(SUBSTITUTE(SUBSTITUTE(C20,CHAR(160)," ")," -","-"),"- ","-")) -> E001-00000129 | F20: 0 | H20: MUÑOZ VERANO JOHN BRACKSON | I20: 45937 | J20: 45937 | K20: 45939 | L20: P00272 | N20: E001-129 | P20: COLABORATIVA S.A.C. | Q20: -200 | R20: -36 | S20: -236 | T20: -236 | V20: PEN | W20: FALSE | X20: Pagado | AB20: Registrado | AN20: =+IF(AM20<>"",AM20,I20) -> 45937 | AO20: =+VLOOKUP(D20,validaciones_json!$AS:$AS,1,0) -> #N/A
A21: FXP/2025/10/0089 | B21: FXP/2025/10/0089 | C21: E001-00000128 | D21: 01-E001-00000128 | E21: =+IF(C21="",SUBSTITUTE(SUBSTITUTE(SUBSTITUTE(B21,CHAR(160)," ")," -","-"),"- ","-"),SUBSTITUTE(SUBSTITUTE(SUBSTITUTE(C21,CHAR(160)," ")," -","-"),"- ","-")) -> E001-00000128 | F21: 0 | H21: MUÑOZ VERANO JOHN BRACKSON | I21: 45937 | J21: 45937 | K21: 45937 | L21: P00274 | P21: COLABORATIVA S.A.C. | Q21: -308 | R21: -55.44 | S21: -363.44 | T21: -363.44 | V21: PEN | W21: FALSE | X21: Pagado | AB21: Registrado | AN21: =+IF(AM21<>"",AM21,I21) -> 45937 | AO21: =+VLOOKUP(D21,validaciones_json!$AS:$AS,1,0) -> #N/A
A22: FXP/2025/10/0088 | B22: FXP/2025/10/0088 | C22: E001-00000067 | D22: 02-E001-00000067 | E22: =+IF(C22="",SUBSTITUTE(SUBSTITUTE(SUBSTITUTE(B22,CHAR(160)," ")," -","-"),"- ","-"),SUBSTITUTE(SUBSTITUTE(SUBSTITUTE(C22,CHAR(160)," ")," -","-"),"- ","-")) -> E001-00000067 | F22: 0 | H22: VENTURA SABINO MIGUEL ANGEL | I22: 45937 | J22: 45937 | K22: 45937 | L22: P00273 | P22: COLABORATIVA S.A.C. | Q22: -880 | S22: -880 | T22: -880 | V22: PEN | W22: FALSE | X22: Pagado | AB22: Registrado | AN22: =+IF(AM22<>"",AM22,I22) -> 45937 | AO22: =+VLOOKUP(D22,validaciones_json!$AS:$AS,1,0) -> #N/A
A23: FXP/2025/10/0114 | B23: FXP/2025/10/0114 | C23: E001-00000016 | D23: 02-E001-00000016 | E23: =+IF(C23="",SUBSTITUTE(SUBSTITUTE(SUBSTITUTE(B23,CHAR(160)," ")," -","-"),"- ","-"),SUBSTITUTE(SUBSTITUTE(SUBSTITUTE(C23,CHAR(160)," ")," -","-"),"- ","-")) -> E001-00000016 | F23: 0 | H23: SALVADOR ARNALDO REYES CHUECAS | I23: 45936 | J23: 45936 | K23: 45943 | L23: P00287 | N23: E001-16 | P23: COLABORATIVA S.A.C. | Q23: -600 | S23: -600 | T23: -600 | V23: PEN | W23: FALSE | X23: Pagado | AB23: Registrado | AN23: =+IF(AM23<>"",AM23,I23) -> 45936 | AO23: =+VLOOKUP(D23,validaciones_json!$AS:$AS,1,0) -> #N/A
A24: FXP/2025/10/0097 | B24: FXP/2025/10/0097 | C24: E001 -38 | D24: 02-E001 -38 | E24: =+IF(C24="",SUBSTITUTE(SUBSTITUTE(SUBSTITUTE(B24,CHAR(160)," ")," -","-"),"- ","-"),SUBSTITUTE(SUBSTITUTE(SUBSTITUTE(C24,CHAR(160)," ")," -","-"),"- ","-")) -> E001-38 | F24: 0 | H24: CARMEN CRUZ MILAGROS ZONALI | I24: 45936 | J24: 45936 | K24: 45939 | L24: P00275 | N24: E001-38 | P24: COLABORATIVA S.A.C. | Q24: -160 | S24: -160 | T24: -160 | V24: PEN | W24: FALSE | X24: Pagado | AB24: Registrado | AN24: =+IF(AM24<>"",AM24,I24) -> 45936 | AO24: =+VLOOKUP(D24,validaciones_json!$AS:$AS,1,0) -> #N/A
A25: FXP/2025/10/0092 | B25: FXP/2025/10/0092 | C25: F001-00025751 | D25: 01-F001-00025751 | E25: =+IF(C25="",SUBSTITUTE(SUBSTITUTE(SUBSTITUTE(B25,CHAR(160)," ")," -","-"),"- ","-"),SUBSTITUTE(SUBSTITUTE(SUBSTITUTE(C25,CHAR(160)," ")," -","-"),"- ","-")) -> F001-00025751 | F25: 0 | H25: TECNOLOGIA FLEXOGRAFICA S.A.C - TECFLEX | I25: 45936 | J25: 45936 | K25: 45936 | L25: P00265 | P25: COLABORATIVA S.A.C. | Q25: -2477 | R25: -445.86 | S25: -2922.86 | T25: -2922.86 | V25: PEN | W25: FALSE | X25: Pagado | AB25: Registrado | AN25: =+IF(AM25<>"",AM25,I25) -> 45936 | AO25: =+VLOOKUP(D25,validaciones_json!$AS:$AS,1,0) -> #N/A
A26: FXP/2025/10/0098 | B26: FXP/2025/10/0098 | C26: 544-4458714229 | D26: 01-544-4458714229 | E26: =+IF(C26="",SUBSTITUTE(SUBSTITUTE(SUBSTITUTE(B26,CHAR(160)," ")," -","-"),"- ","-"),SUBSTITUTE(SUBSTITUTE(SUBSTITUTE(C26,CHAR(160)," ")," -","-"),"- ","-")) -> 544-4458714229 | F26: 0 | H26: LATAM AIRLINES PERU S.A. | I26: 45935 | J26: 45935 | K26: 45939 | L26: P00278 | P26: COLABORATIVA S.A.C. | Q26: -132.78 | R26: -23.9 | S26: -156.68 | T26: -156.68 | V26: PEN | W26: FALSE | X26: Pagado | AB26: Registrado | AN26: =+IF(AM26<>"",AM26,I26) -> 45935 | AO26: =+VLOOKUP(D26,validaciones_json!$AS:$AS,1,0) -> #N/A
A27: FXP/2025/10/0091 | B27: FXP/2025/10/0091 | C27: FP03-00001558 | D27: 01-FP03-00001558 | E27: =+IF(C27="",SUBSTITUTE(SUBSTITUTE(SUBSTITUTE(B27,CHAR(160)," ")," -","-"),"- ","-"),SUBSTITUTE(SUBSTITUTE(SUBSTITUTE(C27,CHAR(160)," ")," -","-"),"- ","-")) -> FP03-00001558 | F27: 0 | H27: ROJAS SIESQUEN CARLOS EDGARDO | I27: 45935 | J27: 45935 | K27: 45937 | P27: COLABORATIVA S.A.C. | Q27: -128.81 | R27: -23.19 | S27: -152 | T27: -152 | V27: PEN | W27: FALSE | X27: Pagado | AB27: Registrado | AN27: =+IF(AM27<>"",AM27,I27) -> 45935 | AO27: =+VLOOKUP(D27,validaciones_json!$AS:$AS,1,0) -> #N/A
A28: FXP/2025/10/0090 | B28: FXP/2025/10/0090 | C28: FF13-00000401 | D28: 01-FF13-00000401 | E28: =+IF(C28="",SUBSTITUTE(SUBSTITUTE(SUBSTITUTE(B28,CHAR(160)," ")," -","-"),"- ","-"),SUBSTITUTE(SUBSTITUTE(SUBSTITUTE(C28,CHAR(160)," ")," -","-"),"- ","-")) -> FF13-00000401 | F28: 0 | H28: LATAM PERU S.A.C. | I28: 45935 | J28: 45935 | K28: 45937 | P28: COLABORATIVA S.A.C. | Q28: -50.85 | R28: -9.15 | S28: -60 | T28: -60 | V28: PEN | W28: FALSE | X28: Pagado | AB28: Registrado | AN28: =+IF(AM28<>"",AM28,I28) -> 45935 | AO28: =+VLOOKUP(D28,validaciones_json!$AS:$AS,1,0) -> #N/A
A29: FXP/2025/10/0086 | B29: FXP/2025/10/0086 | C29: E001-00000004 | D29: 02-E001-00000004 | E29: =+IF(C29="",SUBSTITUTE(SUBSTITUTE(SUBSTITUTE(B29,CHAR(160)," ")," -","-"),"- ","-"),SUBSTITUTE(SUBSTITUTE(SUBSTITUTE(C29,CHAR(160)," ")," -","-"),"- ","-")) -> E001-00000004 | F29: 0 | H29: SECLEN ZAMORA JAHAIRA VANESSITA | I29: 45935 | J29: 45935 | K29: 45935 | L29: P00269 | N29: E001-4 | P29: COLABORATIVA S.A.C. | Q29: -220 | S29: -220 | T29: -220 | V29: PEN | W29: FALSE | X29: Pagado | AB29: Registrado | AN29: =+IF(AM29<>"",AM29,I29) -> 45935 | AO29: =+VLOOKUP(D29,validaciones_json!$AS:$AS,1,0) -> #N/A
A30: FXP/2025/10/0084 | B30: FXP/2025/10/0084 | C30: E001-00000015 | D30: 02-E001-00000015 | E30: =+IF(C30="",SUBSTITUTE(SUBSTITUTE(SUBSTITUTE(B30,CHAR(160)," ")," -","-"),"- ","-"),SUBSTITUTE(SUBSTITUTE(SUBSTITUTE(C30,CHAR(160)," ")," -","-"),"- ","-")) -> E001-00000015 | F30: 0 | H30: BRAVO MATOS RICARDO ALEJANDRO | I30: 45935 | J30: 45935 | K30: 45937 | L30: P00270 | M30: Pago Honorarios | P30: COLABORATIVA S.A.C. | Q30: -120 | S30: -120 | T30: -120 | V30: PEN | W30: FALSE | X30: Pagado | AB30: Registrado | AN30: =+IF(AM30<>"",AM30,I30) -> 45935 | AO30: =+VLOOKUP(D30,validaciones_json!$AS:$AS,1,0) -> #N/A
A31: FXP/2025/10/0115 | B31: FXP/2025/10/0115 | C31: SB02-0243453637 | D31: 14-SB02-0243453637 | E31: =+IF(C31="",SUBSTITUTE(SUBSTITUTE(SUBSTITUTE(B31,CHAR(160)," ")," -","-"),"- ","-"),SUBSTITUTE(SUBSTITUTE(SUBSTITUTE(C31,CHAR(160)," ")," -","-"),"- ","-")) -> SB02-0243453637 | F31: 0 | H31: America Móvil Perú S.A.C. | I31: 45934 | J31: 45934 | K31: 45944 | L31: P00288 | O31: PENDIENTE DE PAGO | P31: COLABORATIVA S.A.C. | Q31: -36.04 | R31: -6.49 | S31: -42.53 | T31: -42.53 | U31: -42.53 | V31: PEN | W31: FALSE | X31: Sin pagar | AB31: Registrado | AN31: =+IF(AM31<>"",AM31,I31) -> 45934 | AO31: =+VLOOKUP(D31,validaciones_json!$AS:$AS,1,0) -> #N/A
A32: FXP/2025/10/0078 | B32: FXP/2025/10/0078 | C32: F001-00009665 | D32: 01-F001-00009665 | E32: =+IF(C32="",SUBSTITUTE(SUBSTITUTE(SUBSTITUTE(B32,CHAR(160)," ")," -","-"),"- ","-"),SUBSTITUTE(SUBSTITUTE(SUBSTITUTE(C32,CHAR(160)," ")," -","-"),"- ","-")) -> F001-00009665 | F32: 0 | H32: PRECINTOS PERU E.I.R.L | I32: 45932 | J32: 45932 | K32: 45933 | L32: P00264 | P32: COLABORATIVA S.A.C. | Q32: -2002.56 | R32: -360.44 | S32: -2363 | T32: -2363 | V32: PEN | W32: FALSE | X32: Pagado | AB32: Registrado | AN32: =+IF(AM32<>"",AM32,I32) -> 45932 | AO32: =+VLOOKUP(D32,validaciones_json!$AS:$AS,1,0) -> #N/A
A33: FXP/2025/10/0104 | B33: FXP/2025/10/0104 | C33: FE30-00023585 | D33: 01-FE30-00023585 | E33: =+IF(C33="",SUBSTITUTE(SUBSTITUTE(SUBSTITUTE(B33,CHAR(160)," ")," -","-"),"- ","-"),SUBSTITUTE(SUBSTITUTE(SUBSTITUTE(C33,CHAR(160)," ")," -","-"),"- ","-")) -> FE30-00023585 | F33: 0 | H33: Verisure Peru SAC | I33: 45931 | J33: 45931 | K33: 45940 | P33: COLABORATIVA S.A.C. | Q33: -221.82 | R33: -39.93 | S33: -261.75 | T33: -261.75 | V33: PEN | W33: FALSE | X33: Pagado | AB33: Registrado | AN33: =+IF(AM33<>"",AM33,I33) -> 45931 | AO33: =+VLOOKUP(D33,validaciones_json!$AS:$AS,1,0) -> #N/A
A34: FXP/2025/10/0077 | B34: FXP/2025/10/0077 | C34: F004-00027540 | D34: 01-F004-00027540 | E34: =+IF(C34="",SUBSTITUTE(SUBSTITUTE(SUBSTITUTE(B34,CHAR(160)," ")," -","-"),"- ","-"),SUBSTITUTE(SUBSTITUTE(SUBSTITUTE(C34,CHAR(160)," ")," -","-"),"- ","-")) -> F004-00027540 | F34: 0 | H34: J & V MULTIUTILES PUNTO COM S.A.C. | I34: 45931 | J34: 45931 | K34: 45931 | L34: P00259 | P34: COLABORATIVA S.A.C. | Q34: -125.85 | R34: -22.65 | S34: -148.5 | T34: -148.5 | V34: PEN | W34: FALSE | X34: Pagado | AB34: Registrado | AN34: =+IF(AM34<>"",AM34,I34) -> 45931 | AO34: =+VLOOKUP(D34,validaciones_json!$AS:$AS,1,0) -> #N/A
A35: FXP/2025/10/0076 | B35: FXP/2025/10/0076 | C35: F004-00027539 | D35: 01-F004-00027539 | E35: =+IF(C35="",SUBSTITUTE(SUBSTITUTE(SUBSTITUTE(B35,CHAR(160)," ")," -","-"),"- ","-"),SUBSTITUTE(SUBSTITUTE(SUBSTITUTE(C35,CHAR(160)," ")," -","-"),"- ","-")) -> F004-00027539 | F35: 0 | H35: J & V MULTIUTILES PUNTO COM S.A.C. | I35: 45931 | J35: 45931 | K35: 45933 | L35: P00260 | P35: COLABORATIVA S.A.C. | Q35: -677.97 | R35: -122.03 | S35: -800 | T35: -800 | V35: PEN | W35: FALSE | X35: Pagado | AB35: Registrado | AN35: =+IF(AM35<>"",AM35,I35) -> 45931 | AO35: =+VLOOKUP(D35,validaciones_json!$AS:$AS,1,0) -> #N/A
A36: FXP/2025/10/0067 | B36: FXP/2025/10/0067 | C36: FE30-00023070 | D36: 01-FE30-00023070 | E36: =+IF(C36="",SUBSTITUTE(SUBSTITUTE(SUBSTITUTE(B36,CHAR(160)," ")," -","-"),"- ","-"),SUBSTITUTE(SUBSTITUTE(SUBSTITUTE(C36,CHAR(160)," ")," -","-"),"- ","-")) -> FE30-00023070 | F36: 0 | H36: Verisure Peru SAC | I36: 45931 | J36: 45931 | K36: 45932 | L36: P00262 | P36: COLABORATIVA S.A.C. | Q36: -87.29 | R36: -15.71 | S36: -103 | T36: -103 | V36: PEN | W36: FALSE | X36: Pagado | AB36: Registrado | AN36: =+IF(AM36<>"",AM36,I36) -> 45931 | AO36: =+VLOOKUP(D36,validaciones_json!$AS:$AS,1,0) -> #N/A
A37: FXP/2025/10/0087 | B37: FXP/2025/10/0087 | C37: E001-00000037 | D37: 02-E001-00000037 | E37: =+IF(C37="",SUBSTITUTE(SUBSTITUTE(SUBSTITUTE(B37,CHAR(160)," ")," -","-"),"- ","-"),SUBSTITUTE(SUBSTITUTE(SUBSTITUTE(C37,CHAR(160)," ")," -","-"),"- ","-")) -> E001-00000037 | F37: 0 | H37: CARMEN CRUZ MILAGROS ZONALI | I37: 45924 | J37: 45930 | K37: 45924 | L37: P00243 | N37: E001-37 | P37: COLABORATIVA S.A.C. | Q37: -175 | S37: -175 | T37: -175 | V37: PEN | W37: FALSE | X37: Pagado | AB37: Registrado | AN37: =+IF(AM37<>"",AM37,I37) -> 45924 | AO37: =+VLOOKUP(D37,validaciones_json!$AS:$AS,1,0) -> #N/A
A38: FXP/2025/10/0083 | B38: FXP/2025/10/0083 | C38: S106-0014885947 | D38: 14-S106-0014885947 | E38: =+IF(C38="",SUBSTITUTE(SUBSTITUTE(SUBSTITUTE(B38,CHAR(160)," ")," -","-"),"- ","-"),SUBSTITUTE(SUBSTITUTE(SUBSTITUTE(C38,CHAR(160)," ")," -","-"),"- ","-")) -> S106-0014885947 | F38: 0 | H38: SERVICIO DE AGUA POTABLE Y ALCANTARILLADO DE LIMA | I38: 45920 | J38: 45930 | K38: 45936 | L38: P00268 | P38: COLABORATIVA S.A.C. | Q38: -6.19 | R38: -1.11 | S38: -7.3 | T38: -7.3 | U38: -7.3 | V38: PEN | W38: FALSE | X38: Sin pagar | AB38: Registrado | AN38: =+IF(AM38<>"",AM38,I38) -> 45920 | AO38: =+VLOOKUP(D38,validaciones_json!$AS:$AS,1,0) -> #N/A
A39: FXP/2025/10/0081 | B39: FXP/2025/10/0081 | C39: SB01-0571094872 | D39: 14-SB01-0571094872 | E39: =+IF(C39="",SUBSTITUTE(SUBSTITUTE(SUBSTITUTE(B39,CHAR(160)," ")," -","-"),"- ","-"),SUBSTITUTE(SUBSTITUTE(SUBSTITUTE(C39,CHAR(160)," ")," -","-"),"- ","-")) -> SB01-0571094872 | F39: 0 | H39: America Móvil Perú S.A.C. | I39: 45925 | J39: 45930 | K39: 45936 | L39: P00267 | P39: COLABORATIVA S.A.C. | Q39: -76.76 | R39: -13.82 | S39: -90.58 | T39: -90.58 | U39: -90.58 | V39: PEN | W39: FALSE | X39: Sin pagar | AB39: Registrado | AN39: =+IF(AM39<>"",AM39,I39) -> 45925 | AO39: =+VLOOKUP(D39,validaciones_json!$AS:$AS,1,0) -> #N/A
A40: FXP/2025/10/0080 | B40: FXP/2025/10/0080 | C40: SB01-0571233027 | D40: 14-SB01-0571233027 | E40: =+IF(C40="",SUBSTITUTE(SUBSTITUTE(SUBSTITUTE(B40,CHAR(160)," ")," -","-"),"- ","-"),SUBSTITUTE(SUBSTITUTE(SUBSTITUTE(C40,CHAR(160)," ")," -","-"),"- ","-")) -> SB01-0571233027 | F40: 0 | H40: America Móvil Perú S.A.C. | I40: 45925 | J40: 45930 | K40: 45936 | L40: P00266 | P40: COLABORATIVA S.A.C. | Q40: -26.15 | R40: -4.71 | S40: -30.86 | T40: -30.86 | U40: -30.86 | V40: PEN | W40: FALSE | X40: Sin pagar | AB40: Registrado | AN40: =+IF(AM40<>"",AM40,I40) -> 45925 | AO40: =+VLOOKUP(D40,validaciones_json!$AS:$AS,1,0) -> #N/A
...

Sheet Hoja1
B2: Número
B3: Número de Documento
B4: VAOPE Codigo Evento
B5: Evento
B6: Nombre del contacto a mostrar en la factura
B7: Fecha de factura
B8: Fecha
B9: Fecha de vencimiento
B10: Origen
B11: Referencia de pago
B12: Referencia
B13: Actividades
... B26: Estado

Sheet Validaciones_odooInterface
B6: Nro productos | E6: Importe sin IGV por estado factura | H6: Importe sin IGV por nombre producto | K6: Importe sin IGV por Organizador | Q6: Importe sin IGV por Distribucion analitica | T6: Importe sin IGV por 1.Fecha Evento o 2.Fecha factura | Z6: Importe sin IGV por 1.Fecha Evento o 2.Fecha factura
B8: Etiquetas de fila | C8: Cuenta de Fecha de factura | E8: Etiquetas de fila | F8: Importe sin impuestos firmado | H8: Etiquetas de fila | I8: Importe sin impuestos firmado | K8: Etiquetas de fila | L8: Cuenta de Fecha de factura | M8: Importe sin impuestos firmado | N8: Suma de Impuesto firmado | O8: Suma de Total firmado | Q8: Etiquetas de fila | R8: Importe sin impuestos firmado | T8: Etiquetas de fila | U8: Cuenta de Fecha de factura | V8: Importe sin impuestos firmado | W8: Suma de Impuesto firmado | X8: Suma de Total firmado | Z8: Etiquetas de fila | AA8: Cuenta de Fecha de factura | AB8: Importe sin impuestos firmado | AC8: Suma de Impuesto firmado | AD8: Suma de Total firmado
B9: Registrado | C9: 424 | E9: Registrado | F9: -671100.63 | H9: (en blanco) | I9: -671100.63 | K9: FLINK S.A.C. | L9: 12 | M9: -37067.68 | N9: -6672.32 | O9: -43740 | Q9: (en blanco) | R9: -671100.63 | T9: 45800 | U9: 1 | V9: -2724.59 | W9: -490.41 | X9: -3215 | Z9: FXP/2025/10/0117 | AA9: 1 | AB9: -2170 | AD9: -2170
B10: Total general | C10: 424 | E10: Total general | F10: -671100.63 | H10: Total general | I10: -671100.63 | K10: VENTURA SABINO MIGUEL ANGEL | L10: 11 | M10: -17409.49 | N10: -30.51 | O10: -17440 | Q10: Total general | R10: -671100.63 | T10: 45810 | U10: 5 | V10: -11226.43 | W10: -1993.77 | X10: -13220.2 | Z10: FXP/2025/10/0116 | AA10: 1 | AB10: -450 | AC10: -81 | AD10: -531
K11: PRAGMATIC S.A.C. | L11: 10 | M11: -11190 | N11: -2014.2 | O11: -13204.2 | T11: 45812 | U11: 4 | V11: -7486.7 | W11: -217.83 | X11: -7704.53 | Z11: FXP/2025/10/0113 | AA11: 1 | AB11: -3550 | AD11: -3550
K12: GUTIERREZ PETIT MARIA ANGEL | L12: 1 | M12: -3550 | O12: -3550 | T12: 45821 | U12: 4 | V12: -993.85 | W12: -177.65 | X12: -1171.5 | Z12: FXP/2025/10/0109 | AA12: 1 | AB12: -1640 | AD12: -1640
K13: CARMEN CRUZ MILAGROS ZONALI | L13: 5 | M13: -2402.37 | N13: -52.63 | O13: -2455 | T13: 45831 | U13: 2 | V13: -700 | W13: -126 | X13: -826 | Z13: FXP/2025/10/0111 | AA13: 1 | AB13: -225 | AC13: -40.5 | AD13: -265.5
K14: MAPFRE PERU S.A. | L14: 6 | M14: -850 | N14: -153 | O14: -1003 | T14: 45944 | U14: 1 | V14: -2170 | X14: -2170 | Z14: FXP/2025/10/0112 | AA14: 1 | AB14: -5400 | AD14: -5400
E15: Importe sin IGV por estado factura | K15: VARGAS HUARCAYA DANIELA RUBI | L15: 1 | M15: -5400 | O15: -5400 | T15: 45943 | U15: 2 | V15: -4000 | W15: -81 | X15: -4081 | Z15: FXP/2025/10/0110 | AA15: 1 | AB15: -101.69 | AC15: -18.31 | AD15: -120
K16: DOLCE CAPRICCIO SAC | L16: 2 | M16: -196.69 | N16: -18.31 | O16: -215 | T16: 45942 | U16: 1 | V16: -1640 | X16: -1640 | Z16: FXP/2025/10/0108 | AA16: 1 | AB16: -7000 | AD16: -7000
E17: Etiquetas de fila | F17: Suma de Impuesto firmado | K17: GALVAN VARGAS DAYANA LIZBETH | L17: 1 | M17: -7000 | O17: -7000 | T17: 45941 | U17: 1 | V17: -225 | W17: -40.5 | X17: -265.5 | Z17: FXP/2025/10/0106 | AA17: 1 | AB17: -338.98 | AC17: -61.02 | AD17: -400
E18: Registrado | F18: -100981.32 | K18: SOLANO CALDERON JUAN ALONSO | L18: 2 | M18: -738.98 | N18: -61.02 | O18: -800 | T18: 45940 | U18: 5 | V18: -13137.28 | W18: -132.72 | X18: -13270 | Z18: FXP/2025/10/0105 | AA18: 1 | AB18: -296.61 | AC18: -53.39 | AD18: -350
E19: Total general | F19: -100981.32 | K19: ESPINO MORI LEANDRO JOAQUIN | L19: 7 | M19: -3106.61 | N19: -53.39 | O19: -3160 | T19: 45931 | U19: 5 | V19: -1184.63 | W19: -200.32 | X19: -1384.95 | Z19: FXP/2025/10/0102 | AA19: 1 | AB19: -71.7 | AD19: -71.7
K20: PANIFICADORA LA NUEZ SAC | L20: 1 | M20: -71.7 | O20: -71.7 | T20: 45937 | U20: 5 | V20: -2715.8 | W20: -307.44 | X20: -3023.24 | Z20: FXP/2025/10/0101 | AA20: 1 | AB20: -127.8 | AD20: -127.8
K21: INVERSIONES SAP S.A. | L21: 1 | M21: -127.8 | O21: -127.8 | T21: 45936 | U21: 4 | V21: -3301.5 | W21: -445.86 | X21: -3747.36 | Z21: FXP/2025/10/0100 | AA21: 1 | AB21: -64.5 | AD21: -64.5
K22: ORIENTAL GOURMET S.A. | L22: 2 | M22: -117.47 | N22: -9.53 | O22: -127 | T22: 45939 | U22: 2 | V22: -1462 | W22: -180 | X22: -1642 | Z22: FXP/2025/10/0099 | AA22: 1 | AB22: -462 | AD22: -462
E23: Importe sin IGV por estado factura | K23: MALBEC SAC | L23: 2 | M23: -906 | O23: -906 | T23: 45938 | U23: 2 | V23: -661.02 | W23: -119.01 | X23: -780.03 | Z23: FXP/2025/10/0107 | AA23: 1 | AB23: -1000 | AC23: -180 | AD23: -1180
K24: KUNTUR PRO S.A.C. | L24: 2 | M24: -6050 | N24: -1089 | O24: -7139 | T24: 45935 | U24: 5 | V24: -652.44 | W24: -56.24 | X24: -708.68 | Z24: FXP/2025/10/0096 | AA24: 1 | AB24: -110.17 | AC24: -19.84 | AD24: -130.01
E25: Etiquetas de fila | F25: Suma de Total firmado | K25: EURO CARS PERU S.A.C. | L25: 2 | M25: -661.02 | N25: -119.01 | O25: -780.03 | T25: 45934 | U25: 1 | V25: -36.04 | W25: -6.49 | X25: -42.53 | Z25: FXP/2025/10/0095 | AA25: 1 | AB25: -550.85 | AC25: -99.17 | AD25: -650.02
E26: Registrado | F26: -772081.95 | K26: MUÑOZ VERANO JOHN BRACKSON | L26: 38 | M26: -46586 | N26: -8234.28 | O26: -54820.28 | T26: 45932 | U26: 1 | V26: -2002.56 | W26: -360.44 | X26: -2363 | Z26: FXP/2025/10/0094 | AA26: 1 | AB26: -1200 | AC26: -216 | AD26: -1416
E27: Total general | F27: -772081.95 | K27: SALVADOR ARNALDO REYES CHUECAS | L27: 4 | M27: -2883.59 | O27: -2883.59 | T27: 45924 | U27: 8 | V27: -2569.73 | W27: -352.07 | X27: -2921.8 | Z27: FXP/2025/10/0093 | AA27: 1 | AB27: -200 | AC27: -36 | AD27: -236
K28: TECNOLOGIA FLEXOGRAFICA S.A.C - TECFLEX | L28: 13 | M28: -16433.6 | N28: -2958.04 | O28: -19391.64 | T28: 45920 | U28: 1 | V28: -6.19 | W28: -1.11 | X28: -7.3 | Z28: FXP/2025/10/0089 | AA28: 1 | AB28: -308 | AC28: -55.44 | AD28: -363.44
K29: LATAM AIRLINES PERU S.A. | L29: 4 | M29: -2415.3 | N29: -434.75 | O29: -2850.05 | T29: 45925 | U29: 6 | V29: -1144.74 | W29: -206.06 | X29: -1350.8 | Z29: FXP/2025/10/0088 | AA29: 1 | AB29: -880 | AD29: -880
K30: ROJAS SIESQUEN CARLOS EDGARDO | L30: 1 | M30: -128.81 | N30: -23.19 | O30: -152 | T30: 45918 | U30: 5 | V30: -3154.07 | W30: -422.96 | X30: -3577.03 | Z30: FXP/2025/10/0114 | AA30: 1 | AB30: -600 | AD30: -600
K31: LATAM PERU S.A.C. | L31: 1 | M31: -50.85 | N31: -9.15 | O31: -60 | T31: 45929 | U31: 7 | V31: -18399.45 | W31: -2706.59 | X31: -21106.04 | Z31: FXP/2025/10/0097 | AA31: 1 | AB31: -160 | AD31: -160
K32: SECLEN ZAMORA JAHAIRA VANESSITA | L32: 1 | M32: -220 | O32: -220 | T32: 45930 | U32: 1 | V32: -30 | X32: -30 | Z32: FXP/2025/10/0092 | AA32: 1 | AB32: -2477 | AC32: -445.86 | AD32: -2922.86
K33: BRAVO MATOS RICARDO ALEJANDRO | L33: 1 | M33: -120 | O33: -120 | T33: 45900 | U33: 1 | V33: -86 | X33: -86 | Z33: FXP/2025/10/0098 | AA33: 1 | AB33: -132.78 | AC33: -23.9 | AD33: -156.68
K34: America Móvil Perú S.A.C. | L34: 13 | M34: -469.57 | N34: -84.54 | O34: -554.11 | T34: 45910 | U34: 3 | V34: -378.93 | W34: -27 | X34: -405.93 | Z34: FXP/2025/10/0091 | AA34: 1 | AB34: -128.81 | AC34: -23.19 | AD34: -152
K35: PRECINTOS PERU E.I.R.L | L35: 15 | M35: -61487.25 | N35: -11067.75 | O35: -72555 | T35: 45908 | U35: 2 | V35: -3367.73 | W35: -580.77 | X35: -3948.5 | Z35: FXP/2025/10/0090 | AA35: 1 | AB35: -50.85 | AC35: -9.15 | AD35: -60
K36: Verisure Peru SAC | L36: 11 | M36: -2071.94 | N36: -325.84 | O36: -2397.78 | T36: 45906 | U36: 3 | V36: -358.11 | W36: -9.54 | X36: -367.65 | Z36: FXP/2025/10/0086 | AA36: 1 | AB36: -220 | AD36: -220
K37: J & V MULTIUTILES PUNTO COM S.A.C. | L37: 5 | M37: -1063.57 | N37: -191.43 | O37: -1255 | T37: 45915 | U37: 3 | V37: -2919.8 | X37: -2919.8 | Z37: FXP/2025/10/0084 | AA37: 1 | AB37: -120 | AD37: -120
K38: SERVICIO DE AGUA POTABLE Y ALCANTARILLADO DE LIMA | L38: 3 | M38: -18.73 | N38: -3.37 | O38: -22.1 | T38: 45916 | U38: 3 | V38: -3798.03 | W38: -633.97 | X38: -4432 | Z38: FXP/2025/10/0115 | AA38: 1 | AB38: -36.04 | AC38: -6.49 | AD38: -42.53
K39: RASH PERU S.R.L | L39: 2 | M39: -653.99 | N39: -117.71 | O39: -771.7 | T39: 45926 | U39: 1 | V39: -538.14 | W39: -96.86 | X39: -635 | Z39: FXP/2025/10/0078 | AA39: 1 | AB39: -2002.56 | AC39: -360.44 | AD39: -2363
K40: SANTOFA E.I.R.L. | L40: 1 | M40: -88.81 | N40: -15.99 | O40: -104.8 | T40: 45917 | U40: 6 | V40: -2625.41 | W40: -467.15 | X40: -3092.56 | Z40: FXP/2025/10/0104 | AA40: 1 | AB40: -221.82 | AC40: -39.93 | AD40: -261.75
K41: COESTI SA | L41: 4 | M41: -512.36 | N41: -11.59 | O41: -523.95 | T41: 45919 | U41: 5 | V41: -3996.7 | W41: -437.78 | X41: -4434.48 | Z41: FXP/2025/10/0077 | AA41: 1 | AB41: -125.85 | AC41: -22.65 | AD41: -148.5
K42: TOOL STORE PERU E.I.R.L. | L42: 1 | M42: -64.4 | N42: -11.59 | O42: -75.99 | T42: 45911 | U42: 6 | V42: -1878.95 | W42: -321.35 | X42: -2200.3 | Z42: FXP/2025/10/0076 | AA42: 1 | AB42: -677.97 | AC42: -122.03 | AD42: -800
K43: PROLIDER EMPRESARIAL S.AC. | L43: 2 | M43: -1433.41 | N43: -116.99 | O43: -1550.4 | T43: 45904 | U43: 8 | V43: -1636.4 | W43: -214.63 | X43: -1851.03 | Z43: FXP/2025/10/0067 | AA43: 1 | AB43: -87.29 | AC43: -15.71 | AD43: -103
K44: YOPO S.A.C. | L44: 6 | M44: -292.44 | N44: -15.56 | O44: -308 | T44: 45923 | U44: 3 | V44: -1068.97 | W44: -91.61 | X44: -1160.58 | Z44: FXP/2025/10/0087 | AA44: 1 | AB44: -175 | AD44: -175
K45: SANKY 10 S.A.C | L45: 1 | M45: -20.9 | O45: -20.9 | T45: 45914 | U45: 1 | V45: -109.32 | W45: -19.68 | X45: -129 | Z45: FXP/2025/10/0083 | AA45: 1 | AB45: -6.19 | AC45: -1.11 | AD45: -7.3
K46: REPRESENTACIONES ALEXIA S.A.C. | L46: 2 | M46: -185.36 | N46: -14.64 | O46: -200 | T46: 45912 | U46: 5 | V46: -1455.68 | W46: -190.02 | X46: -1645.7 | Z46: FXP/2025/10/0081 | AA46: 1 | AB46: -76.76 | AC46: -13.82 | AD46: -90.58
...

Sheet facturas_con_items_json
A1: serie_correlativo | B1: numero | C1: nombre_empresa | D1: fecha_de_emision | E1: hora_de_emision | F1: nom_proveedor | G1: cat_proveedor | H1: tipo_documento | I1: doc_proveedor | J1: items | K1: factura.fecha_emision | L1: factura.cliente | M1: factura.id_cliente | N1: factura.total | O1: factura.moneda | P1: factura.estado | Q1: item.codigo_producto | R1: item.cantidad | S1: item.valor_unitario | T1: item.precio_unitario | U1: item.descuento | V1: item.subtotal | W1: item.porcentaje_de_igv | X1: item.igv | Y1: item.total | Z1: item.moneda | AA1: item.tipo_de_cambio | AB1: item.id_tipo_gasto | AC1: item.nom_tipo_gasto | AD1: item.id_proveedor | AE1: item.id_producto | AF1: item.nom_producto | AG1: item.categoria_producto | AH1: item.id_estado | AI1: item.nombre_estado | AJ1: item.id_cuenta | AK1: item.nom_cuenta | AL1: item.distribucion_analitica | AM1: item.evento.id_evento | AN1: item.evento.nom_evento | AO1: item.evento.fecha_hora_ini_event | AP1: item.evento.fecha_hora_fin_event | AQ1: item.evento.id_organizador | AR1: item.evento.nom_organizador | AS1: item.evento.tipo_organizador | AT1: UNIFICADO | AU1: CONVERSION.item.subtotal | AV1: CONVERSION.item.igv | AW1: CONVERSION.item.total
A2: E001 | B2: 00000068 | C2: COLABORATIVA S.A.C. | D2: 45944 | E2: 45957.499 | F2: VENTURA SABINO MIGUEL ANGEL | H2: RUC | J2: [{'codigo_producto': 2292, 'cantidad': '1', 'valor_unitario': 2170.0, 'precio_unitario': 2170.0, 'descuento': 0.0, 'subtotal': 2170.0, 'porcentaje_de_igv': '0.00', 'igv': 0.0, 'total': 2170.0, 'moneda': '1', 'tipo_de_cambio': 1.0, 'id_tipo_gasto': 5, 'nom_tipo_gasto': 'Otros', 'id_proveedor': 1806, 'id_producto': 31117, 'nom_producto': 'CARPINTERIA', 'categoria_producto': 'EVENTOS', 'id_estado': 'paid', 'nombre_estado': 'Pagado', 'evento': {'id_evento': '', 'nom_evento': '', 'fecha_hora_ini_event': '', 'fecha_hora_fin_event': '', 'id_organizador': '', 'nom_organizador': '', 'tipo_organizador': ''}, 'id_cuenta': 6743, 'nom_cuenta': '6329102 SERVICIOS DIVERSOS', 'distribucion_analitica': [[{'codigo': 138, 'nom_distribucion': 'Administrativo', 'sub_categoria': 'Acondicionamiento', 'porcentaje': '100.00'}]]}] | K2: 45944 | Q2: 2292 | R2: 1 | S2: 2170 | T2: 2170 | U2: 0 | V2: 2170 | W2: 0 | X2: 0 | Y2: 2170 | Z2: 1 | AA2: 1 | AB2: 5 | AC2: Otros | AD2: 1806 | AE2: 31117 | AF2: CARPINTERIA | AG2: EVENTOS | AH2: paid | AI2: Pagado | AJ2: 6743 | AK2: 6329102 SERVICIOS DIVERSOS | AL2: [[{'codigo': 138, 'nom_distribucion': 'Administrativo', 'sub_categoria': 'Acondicionamiento', 'porcentaje': '100.00'}]] | AT2: =+CONCATENATE(A2,"-",B2) -> E001-00000068 | AU2: =+IF(Z2=1,V2,IF(Z2=2,V2*AA2)) -> 2170 | AV2: =+IF(Z2=1,X2,IF(Z2=2,X2*AA2)) -> 0 | AW2: =+IF(Z2=1,Y2,IF(Z2=2,Y2*AA2)) -> 2170
A3: F002 | B3: 00001584 | C3: COLABORATIVA S.A.C. | D3: 45944 | E3: 45957.432 | F3: PRAGMATIC S.A.C. | G3: Proveedor | H3: RUC | I3: 20607097039 | J3: [{'codigo_producto': 1956, 'cantidad': '1', 'valor_unitario': 450.0, 'precio_unitario': 531.0, 'descuento': 0.0, 'subtotal': 450.0, 'porcentaje_de_igv': '18.00', 'igv': 81.0, 'total': 531.0, 'moneda': '1', 'tipo_de_cambio': 1.0, 'id_tipo_gasto': 2, 'nom_tipo_gasto': 'Servicios', 'id_proveedor': 565, 'id_producto': 31114, 'nom_producto': 'SERVICIO DE CAPACITACION', 'categoria_producto': 'EVENTOS', 'id_estado': 'paid', 'nombre_estado': 'Pagado', 'evento': {'id_evento': '', 'nom_evento': '', 'fecha_hora_ini_event': '', 'fecha_hora_fin_event': '', 'id_organizador': '', 'nom_organizador': '', 'tipo_organizador': ''}, 'id_cuenta': 6740, 'nom_cuenta': '6327106 SERVICIOS INFORMATICOS', 'distribucion_analitica': [[{'codigo': '', 'nom_distribucion': '', 'sub_categoria': '', 'porcentaje': '100.00'}]]}] | K3: 45944 | Q3: 1956 | R3: 1 | S3: 450 | T3: 531 | U3: 0 | V3: 450 | W3: 18 | X3: 81 | Y3: 531 | Z3: 1 | AA3: 1 | AB3: 2 | AC3: Servicios | AD3: 565 | AE3: 31114 | AF3: SERVICIO DE CAPACITACION | AG3: EVENTOS | AH3: paid | AI3: Pagado | AJ3: 6740 | AK3: 6327106 SERVICIOS INFORMATICOS | AL3: [[{'codigo': '', 'nom_distribucion': '', 'sub_categoria': '', 'porcentaje': '100.00'}]] | AT3: =+CONCATENATE(A3,"-",B3) -> F002-00001584 | AU3: =+IF(Z3=1,V3,IF(Z3=2,V3*AA3)) -> 450 | AV3: =+IF(Z3=1,X3,IF(Z3=2,X3*AA3)) -> 81 | AW3: =+IF(Z3=1,Y3,IF(Z3=2,Y3*AA3)) -> 531
A4: E001 | B4: 00000005 | C4: COLABORATIVA S.A.C. | D4: 45943 | E4: 45957.529 | F4: GUTIERREZ PETIT MARIA ANGEL | H4: DNI | I4: 61455425 | J4: [{'codigo_producto': 2029, 'cantidad': '1', 'valor_unitario': 3550.0, 'precio_unitario': 3550.0, 'descuento': 0.0, 'subtotal': 3550.0, 'porcentaje_de_igv': '0.00', 'igv': 0.0, 'total': 3550.0, 'moneda': '1', 'tipo_de_cambio': 1.0, 'id_tipo_gasto': 2, 'nom_tipo_gasto': 'Servicios', 'id_proveedor': 6473, 'id_producto': 31041, 'nom_producto': 'Servicio de movilidad', 'categoria_producto': 'EVENTOS', 'id_estado': 'paid', 'nombre_estado': 'Pagado', 'evento': {'id_evento': '', 'nom_evento': '', 'fecha_hora_ini_event': '', 'fecha_hora_fin_event': '', 'id_organizador': '', 'nom_organizador': '', 'tipo_organizador': ''}, 'id_cuenta': 6723, 'nom_cuenta': '6311200 MOVILIDAD', 'distribucion_analitica': [[{'codigo': '', 'nom_distribucion': '', 'sub_categoria': '', 'porcentaje': '100.00'}]]}] | K4: 45943 | Q4: 2029 | R4: 1 | S4: 3550 | T4: 3550 | U4: 0 | V4: 3550 | W4: 0 | X4: 0 | Y4: 3550 | Z4: 1 | AA4: 1 | AB4: 2 | AC4: Servicios | AD4: 6473 | AE4: 31041 | AF4: Servicio de movilidad | AG4: EVENTOS | AH4: paid | AI4: Pagado | AJ4: 6723 | AK4: 6311200 MOVILIDAD | AL4: [[{'codigo': '', 'nom_distribucion': '', 'sub_categoria': '', 'porcentaje': '100.00'}]] | AT4: =+CONCATENATE(A4,"-",B4) -> E001-00000005 | AU4: =+IF(Z4=1,V4,IF(Z4=2,V4*AA4)) -> 3550 | AV4: =+IF(Z4=1,X4,IF(Z4=2,X4*AA4)) -> 0 | AW4: =+IF(Z4=1,Y4,IF(Z4=2,Y4*AA4)) -> 3550
A5: E001 | B5: 00000039 | C5: COLABORATIVA S.A.C. | D5: 45943 | E5: 45957.396 | F5: CARMEN CRUZ MILAGROS ZONALI | H5: RUC | I5: 10767791416 | J5: [{'codigo_producto': 2258, 'cantidad': '1', 'valor_unitario': 1640.0, 'precio_unitario': 1640.0, 'descuento': 0.0, 'subtotal': 1640.0, 'porcentaje_de_igv': '0.00', 'igv': 0.0, 'total': 1640.0, 'moneda': '1', 'tipo_de_cambio': 1.0, 'id_tipo_gasto': 2, 'nom_tipo_gasto': 'Servicios', 'id_proveedor': 1553, 'id_producto': 31013, 'nom_producto': 'SERV VALIDADORES ', 'categoria_producto': 'SERVICIOS', 'id_estado': 'paid', 'nombre_estado': 'Pagado', 'evento': {'id_evento': '', 'nom_evento': '', 'fecha_hora_ini_event': '', 'fecha_hora_fin_event': '', 'id_organizador': '', 'nom_organizador': '', 'tipo_organizador': ''}, 'id_cuenta': 6743, 'nom_cuenta': '6329102 SERVICIOS DIVERSOS', 'distribucion_analitica': [[{'codigo': 103, 'nom_distribucion': 'Validadores', 'sub_categoria': 'Personal temporal', 'porcentaje': '100.00'}]]}] | K5: 45943 | Q5: 2258 | R5: 1 | S5: 1640 | T5: 1640 | U5: 0 | V5: 1640 | W5: 0 | X5: 0 | Y5: 1640 | Z5: 1 | AA5: 1 | AB5: 2 | AC5: Servicios | AD5: 1553 | AE5: 31013 | AF5: SERV VALIDADORES | AG5: SERVICIOS | AH5: paid | AI5: Pagado | AJ5: 6743 | AK5: 6329102 SERVICIOS DIVERSOS | AL5: [[{'codigo': 103, 'nom_distribucion': 'Validadores', 'sub_categoria': 'Personal temporal', 'porcentaje': '100.00'}]] | AT5: =+CONCATENATE(A5,"-",B5) -> E001-00000039 | AU5: =+IF(Z5=1,V5,IF(Z5=2,V5*AA5)) -> 1640 | AV5: =+IF(Z5=1,X5,IF(Z5=2,X5*AA5)) -> 0 | AW5: =+IF(Z5=1,Y5,IF(Z5=2,Y5*AA5)) -> 1640
A6: F052 | B6: 01689541 | C6: COLABORATIVA S.A.C. | D6: 45943 | E6: 45957.517 | F6: MAPFRE PERU S.A. | G6: Proveedor | H6: RUC | I6: 20517182673 | J6: [{'codigo_producto': 1857, 'cantidad': '4', 'valor_unitario': 56.25, 'precio_unitario': 66.375, 'descuento': 0.0, 'subtotal': 225.0, 'porcentaje_de_igv': '18.00', 'igv': 40.5, 'total': 265.5, 'moneda': '1', 'tipo_de_cambio': 1.0, 'id_tipo_gasto': 5, 'nom_tipo_gasto': 'Otros', 'id_proveedor': 529, 'id_producto': 31036, 'nom_producto': 'SCTR', 'categoria_producto': 'EVENTOS', 'id_estado': 'paid', 'nombre_estado': 'Pagado', 'evento': {'id_evento': '', 'nom_evento': '', 'fecha_hora_ini_event': '', 'fecha_hora_fin_event': '', 'id_organizador': '', 'nom_organizador': '', 'tipo_organizador': ''}, 'id_cuenta': 6797, 'nom_cuenta': '6511101 SEGURO SCTR', 'distribucion_analitica': [[{'codigo': 130, 'nom_distribucion': 'RR.HH', 'sub_categoria': 'Seguridad y salud laboral', 'porcentaje': '100.00'}]]}] | K6: 45943 | Q6: 1857 | R6: 4 | S6: 56.25 | T6: 66.375 | U6: 0 | V6: 225 | W6: 18 | X6: 40.5 | Y6: 265.5 | Z6: 1 | AA6: 1 | AB6: 5 | AC6: Otros | AD6: 529 | AE6: 31036 | AF6: SCTR | AG6: EVENTOS | AH6: paid | AI6: Pagado | AJ6: 6797 | AK6: 6511101 SEGURO SCTR | AL6: [[{'codigo': 130, 'nom_distribucion': 'RR.HH', 'sub_categoria': 'Seguridad y salud laboral', 'porcentaje': '100.00'}]] | AT6: =+CONCATENATE(A6,"-",B6) -> F052-01689541 | AU6: =+IF(Z6=1,V6,IF(Z6=2,V6*AA6)) -> 225 | AV6: =+IF(Z6=1,X6,IF(Z6=2,X6*AA6)) -> 40.5 | AW6: =+IF(Z6=1,Y6,IF(Z6=2,Y6*AA6)) -> 265.5
A7: F250 | B7: 00000900 | C7: COLABORATIVA S.A.C. | D7: 45943 | E7: 45957.441 | F7: DOLCE CAPRICCIO SAC | G7: Proveedor | H7: RUC | I7: 20475815247 | J7: [{'codigo_producto': 1957, 'cantidad': '1', 'valor_unitario': 101.69, 'precio_unitario': 120.0, 'descuento': 0.0, 'subtotal': 101.69, 'porcentaje_de_igv': '18.01', 'igv': 18.310000000000002, 'total': 120.0, 'moneda': '1', 'tipo_de_cambio': 1.0, 'id_tipo_gasto': 5, 'nom_tipo_gasto': 'Otros', 'id_proveedor': 514, 'id_producto': 31017, 'nom_producto': 'TORTA', 'categoria_producto': 'EVENTOS', 'id_estado': 'paid', 'nombre_estado': 'Pagado', 'evento': {'id_evento': '', 'nom_evento': '', 'fecha_hora_ini_event': '', 'fecha_hora_fin_event': '', 'id_organizador': '', 'nom_organizador': '', 'tipo_organizador': ''}, 'id_cuenta': 6726, 'nom_cuenta': '6314100 AlimentaciÃ³n', 'distribucion_analitica': [[{'codigo': 97, 'nom_distribucion': 'RR.HH', 'sub_categoria': 'Bienestar', 'porcentaje': '100.00'}]]}] | K7: 45943 | Q7: 1957 | R7: 1 | S7: 101.69 | T7: 120 | U7: 0 | V7: 101.69 | W7: 18.01 | X7: 18.31 | Y7: 120 | Z7: 1 | AA7: 1 | AB7: 5 | AC7: Otros | AD7: 514 | AE7: 31017 | AF7: TORTA | AG7: EVENTOS | AH7: paid | AI7: Pagado | AJ7: 6726 | AK7: 6314100 AlimentaciÃ³n | AL7: [[{'codigo': 97, 'nom_distribucion': 'RR.HH', 'sub_categoria': 'Bienestar', 'porcentaje': '100.00'}]] | AT7: =+CONCATENATE(A7,"-",B7) -> F250-00000900 | AU7: =+IF(Z7=1,V7,IF(Z7=2,V7*AA7)) -> 101.69 | AV7: =+IF(Z7=1,X7,IF(Z7=2,X7*AA7)) -> 18.31 | AW7: =+IF(Z7=1,Y7,IF(Z7=2,Y7*AA7)) -> 120
A8: E001 | B8: 20 | C8: COLABORATIVA S.A.C. | D8: 45943 | E8: 45957.521 | F8: VARGAS HUARCAYA DANIELA RUBI | H8: DNI | I8: 75871275 | J8: [{'codigo_producto': 1939, 'cantidad': '1', 'valor_unitario': 5400.0, 'precio_unitario': 5400.0, 'descuento': 0.0, 'subtotal': 5400.0, 'porcentaje_de_igv': '0.00', 'igv': 0.0, 'total': 5400.0, 'moneda': '1', 'tipo_de_cambio': 1.0, 'id_tipo_gasto': 2, 'nom_tipo_gasto': 'Servicios', 'id_proveedor': 6339, 'id_producto': 31001, 'nom_producto': 'SERVICIO DE SUPERVISION', 'categoria_producto': 'EVENTOS', 'id_estado': 'paid', 'nombre_estado': 'Pagado', 'evento': {'id_evento': '', 'nom_evento': '', 'fecha_hora_ini_event': '', 'fecha_hora_fin_event': '', 'id_organizador': '', 'nom_organizador': '', 'tipo_organizador': ''}, 'id_cuenta': 6743, 'nom_cuenta': '6329102 SERVICIOS DIVERSOS', 'distribucion_analitica': [[{'codigo': 103, 'nom_distribucion': 'Validadores', 'sub_categoria': 'Personal temporal', 'porcentaje': '100.00'}]]}] | K8: 45943 | Q8: 1939 | R8: 1 | S8: 5400 | T8: 5400 | U8: 0 | V8: 5400 | W8: 0 | X8: 0 | Y8: 5400 | Z8: 1 | AA8: 1 | AB8: 2 | AC8: Servicios | AD8: 6339 | AE8: 31001 | AF8: SERVICIO DE SUPERVISION | AG8: EVENTOS | AH8: paid | AI8: Pagado | AJ8: 6743 | AK8: 6329102 SERVICIOS DIVERSOS | AL8: [[{'codigo': 103, 'nom_distribucion': 'Validadores', 'sub_categoria': 'Personal temporal', 'porcentaje': '100.00'}]] | AT8: =+CONCATENATE(A8,"-",B8) -> E001-20 | AU8: =+IF(Z8=1,V8,IF(Z8=2,V8*AA8)) -> 5400 | AV8: =+IF(Z8=1,X8,IF(Z8=2,X8*AA8)) -> 0 | AW8: =+IF(Z8=1,Y8,IF(Z8=2,Y8*AA8)) -> 5400
A9: E001 | B9: 18 | C9: COLABORATIVA S.A.C. | D9: 45940 | E9: 45957.747 | F9: GALVAN VARGAS DAYANA LIZBETH | H9: DNI | I9: 60680641 | J9: [{'codigo_producto': 1939, 'cantidad': '1', 'valor_unitario': 7000.0, 'precio_unitario': 7000.0, 'descuento': 0.0, 'subtotal': 7000.0, 'porcentaje_de_igv': '0.00', 'igv': 0.0, 'total': 7000.0, 'moneda': '1', 'tipo_de_cambio': 1.0, 'id_tipo_gasto': 2, 'nom_tipo_gasto': 'Servicios', 'id_proveedor': 6338, 'id_producto': 30999, 'nom_producto': 'SERVICIO DE SUPERVISION', 'categoria_producto': 'EVENTOS', 'id_estado': 'paid', 'nombre_estado': 'Pagado', 'evento': {'id_evento': '', 'nom_evento': '', 'fecha_hora_ini_event': '', 'fecha_hora_fin_event': '', 'id_organizador': '', 'nom_organizador': '', 'tipo_organizador': ''}, 'id_cuenta': 6743, 'nom_cuenta': '6329102 SERVICIOS DIVERSOS', 'distribucion_analitica': [[{'codigo': 103, 'nom_distribucion': 'Validadores', 'sub_categoria': 'Personal temporal', 'porcentaje': '100.00'}]]}] | K9: 45940 | Q9: 1939 | R9: 1 | S9: 7000 | T9: 7000 | U9: 0 | V9: 7000 | W9: 0 | X9: 0 | Y9: 7000 | Z9: 1 | AA9: 1 | AB9: 2 | AC9: Servicios | AD9: 6338 | AE9: 30999 | AF9: SERVICIO DE SUPERVISION | AG9: EVENTOS | AH9: paid | AI9: Pagado | AJ9: 6743 | AK9: 6329102 SERVICIOS DIVERSOS | AL9: [[{'codigo': 103, 'nom_distribucion': 'Validadores', 'sub_categoria': 'Personal temporal', 'porcentaje': '100.00'}]] | AT9: =+CONCATENATE(A9,"-",B9) -> E001-18 | AU9: =+IF(Z9=1,V9,IF(Z9=2,V9*AA9)) -> 7000 | AV9: =+IF(Z9=1,X9,IF(Z9=2,X9*AA9)) -> 0 | AW9: =+IF(Z9=1,Y9,IF(Z9=2,Y9*AA9)) -> 7000
A10: E001 | B10: 00000057 | C10: COLABORATIVA S.A.C. | D10: 45940 | E10: 45957.49 | F10: SOLANO CALDERON JUAN ALONSO | H10: RUC | I10: 10708131917 | J10: [{'codigo_producto': 1808, 'cantidad': '1', 'valor_unitario': 338.98, 'precio_unitario': 400.0, 'descuento': 0.0, 'subtotal': 338.98, 'porcentaje_de_igv': '18.00', 'igv': 61.01999999999998, 'total': 400.0, 'moneda': '1', 'tipo_de_cambio': 1.0, 'id_tipo_gasto': 2, 'nom_tipo_gasto': 'Servicios', 'id_proveedor': 1816, 'id_producto': 30981, 'nom_producto': 'Asesoria legal', 'categoria_producto': 'SERVICIOS', 'id_estado': 'paid', 'nombre_estado': 'Pagado', 'evento': {'id_evento': '', 'nom_evento': '', 'fecha_hora_ini_event': '', 'fecha_hora_fin_event': '', 'id_organizador': '', 'nom_organizador': '', 'tipo_organizador': ''}, 'id_cuenta': 877, 'nom_cuenta': '6329000 AsesorÃ­a y consultorÃ­a - Otros', 'distribucion_analitica': [[{'codigo': 57, 'nom_distribucion': 'Administrativo', 'sub_categoria': 'Legal', 'porcentaje': '100.00'}]]}] | K10: 45940 | Q10: 1808 | R10: 1 | S10: 338.98 | T10: 400 | U10: 0 | V10: 338.98 | W10: 18 | X10: 61.02 | Y10: 400 | Z10: 1 | AA10: 1 | AB10: 2 | AC10: Servicios | AD10: 1816 | AE10: 30981 | AF10: Asesoria legal | AG10: SERVICIOS | AH10: paid | AI10: Pagado | AJ10: 877 | AK10: 6329000 AsesorÃ­a y consultorÃ­a - Otros | AL10: [[{'codigo': 57, 'nom_distribucion': 'Administrativo', 'sub_categoria': 'Legal', 'porcentaje': '100.00'}]] | AT10: =+CONCATENATE(A10,"-",B10) -> E001-00000057 | AU10: =+IF(Z10=1,V10,IF(Z10=2,V10*AA10)) -> 338.98 | AV10: =+IF(Z10=1,X10,IF(Z10=2,X10*AA10)) -> 61.02 | AW10: =+IF(Z10=1,Y10,IF(Z10=2,Y10*AA10)) -> 400
A11: E001 | B11: 00000026 | C11: COLABORATIVA S.A.C. | D11: 45940 | E11: 45957.489 | F11: ESPINO MORI LEANDRO JOAQUIN | H11: RUC | I11: 10712300251 | J11: [{'codigo_producto': 1808, 'cantidad': '1', 'valor_unitario': 296.61, 'precio_unitario': 350.0, 'descuento': 0.0, 'subtotal': 296.61, 'porcentaje_de_igv': '18.00', 'igv': 53.389999999999986, 'total': 350.0, 'moneda': '1', 'tipo_de_cambio': 1.0, 'id_tipo_gasto': 2, 'nom_tipo_gasto': 'Servicios', 'id_proveedor': 1642, 'id_producto': 30978, 'nom_producto': 'Asesoria legal', 'categoria_producto': 'SERVICIOS', 'id_estado': 'paid', 'nombre_estado': 'Pagado', 'evento': {'id_evento': '', 'nom_evento': '', 'fecha_hora_ini_event': '', 'fecha_hora_fin_event': '', 'id_organizador': '', 'nom_organizador': '', 'tipo_organizador': ''}, 'id_cuenta': 877, 'nom_cuenta': '6329000 AsesorÃ­a y consultorÃ­a - Otros', 'distribucion_analitica': [[{'codigo': 57, 'nom_distribucion': 'Administrativo', 'sub_categoria': 'Legal', 'porcentaje': '100.00'}]]}] | K11: 45940 | Q11: 1808 | R11: 1 | S11: 296.61 | T11: 350 | U11: 0 | V11: 296.61 | W11: 18 | X11: 53.39 | Y11: 350 | Z11: 1 | AA11: 1 | AB11: 2 | AC11: Servicios | AD11: 1642 | AE11: 30978 | AF11: Asesoria legal | AG11: SERVICIOS | AH11: paid | AI11: Pagado | AJ11: 877 | AK11: 6329000 AsesorÃ­a y consultorÃ­a - Otros | AL11: [[{'codigo': 57, 'nom_distribucion': 'Administrativo', 'sub_categoria': 'Legal', 'porcentaje': '100.00'}]] | AT11: =+CONCATENATE(A11,"-",B11) -> E001-00000026 | AU11: =+IF(Z11=1,V11,IF(Z11=2,V11*AA11)) -> 296.61 | AV11: =+IF(Z11=1,X11,IF(Z11=2,X11*AA11)) -> 53.39 | AW11: =+IF(Z11=1,Y11,IF(Z11=2,Y11*AA11)) -> 350
A12: E001 | B12: 00000013 | C12: COLABORATIVA S.A.C. | D12: 45940 | E12: 45957.536 | F12: KUNTUR PRO S.A.C. | H12: RUC | I12: 20614142651 | J12: [{'codigo_producto': 2313, 'cantidad': '1', 'valor_unitario': 1000.0, 'precio_unitario': 1180.0, 'descuento': 0.0, 'subtotal': 1000.0, 'porcentaje_de_igv': '18.00', 'igv': 180.0, 'total': 1180.0, 'moneda': '1', 'tipo_de_cambio': 1.0, 'id_tipo_gasto': 5, 'nom_tipo_gasto': 'Otros', 'id_proveedor': 2741, 'id_producto': 30984, 'nom_producto': 'PRODUCCION', 'categoria_producto': 'EVENTOS', 'id_estado': 'paid', 'nombre_estado': 'Pagado', 'evento': {'id_evento': '', 'nom_evento': '', 'fecha_hora_ini_event': '', 'fecha_hora_fin_event': '', 'id_organizador': '', 'nom_organizador': '', 'tipo_organizador': ''}, 'id_cuenta': 6743, 'nom_cuenta': '6329102 SERVICIOS DIVERSOS', 'distribucion_analitica': [[{'codigo': 96, 'nom_distribucion': 'RR.HH', 'sub_categoria': 'Act. de IntegraciÃ³n', 'porcentaje': '100.00'}]]}] | K12: 45940 | Q12: 2313 | R12: 1 | S12: 1000 | T12: 1180 | U12: 0 | V12: 1000 | W12: 18 | X12: 180 | Y12: 1180 | Z12: 1 | AA12: 1 | AB12: 5 | AC12: Otros | AD12: 2741 | AE12: 30984 | AF12: PRODUCCION | AG12: EVENTOS | AH12: paid | AI12: Pagado | AJ12: 6743 | AK12: 6329102 SERVICIOS DIVERSOS | AL12: [[{'codigo': 96, 'nom_distribucion': 'RR.HH', 'sub_categoria': 'Act. de IntegraciÃ³n', 'porcentaje': '100.00'}]] | AT12: =+CONCATENATE(A12,"-",B12) -> E001-00000013 | AU12: =+IF(Z12=1,V12,IF(Z12=2,V12*AA12)) -> 1000 | AV12: =+IF(Z12=1,X12,IF(Z12=2,X12*AA12)) -> 180 | AW12: =+IF(Z12=1,Y12,IF(Z12=2,Y12*AA12)) -> 1180
A13: F003 | B13: 00001183 | C13: COLABORATIVA S.A.C. | D13: 45940 | E13: 45957.395 | F13: MALBEC SAC | H13: RUC | I13: 20606014113 | J13: [{'codigo_producto': 1912, 'cantidad': '1', 'valor_unitario': 462.0, 'precio_unitario': 462.0, 'descuento': 0.0, 'subtotal': 462.0, 'porcentaje_de_igv': '0.00', 'igv': 0.0, 'total': 462.0, 'moneda': '1', 'tipo_de_cambio': 1.0, 'id_tipo_gasto': 5, 'nom_tipo_gasto': 'Otros', 'id_proveedor': 1529, 'id_producto': 30953, 'nom_producto': 'ALMUERZO', 'categoria_producto': 'EVENTOS', 'id_estado': 'paid', 'nombre_estado': 'Pagado', 'evento': {'id_evento': '', 'nom_evento': '', 'fecha_hora_ini_event': '', 'fecha_hora_fin_event': '', 'id_organizador': '', 'nom_organizador': '', 'tipo_organizador': ''}, 'id_cuenta': 6726, 'nom_cuenta': '6314100 AlimentaciÃ³n', 'distribucion_analitica': [[{'codigo': 145, 'nom_distribucion': 'Administrativo', 'sub_categoria': 'Gerencia', 'porcentaje': '100.00'}]]}] | K13: 45940 | Q13: 1912 | R13: 1 | S13: 462 | T13: 462 | U13: 0 | V13: 462 | W13: 0 | X13: 0 | Y13: 462 | Z13: 1 | AA13: 1 | AB13: 5 | AC13: Otros | AD13: 1529 | AE13: 30953 | AF13: ALMUERZO | AG13: EVENTOS | AH13: paid | AI13: Pagado | AJ13: 6726 | AK13: 6314100 AlimentaciÃ³n | AL13: [[{'codigo': 145, 'nom_distribucion': 'Administrativo', 'sub_categoria': 'Gerencia', 'porcentaje': '100.00'}]] | AT13: =+CONCATENATE(A13,"-",B13) -> F003-00001183 | AU13: =+IF(Z13=1,V13,IF(Z13=2,V13*AA13)) -> 462 | AV13: =+IF(Z13=1,X13,IF(Z13=2,X13*AA13)) -> 0 | AW13: =+IF(Z13=1,Y13,IF(Z13=2,Y13*AA13)) -> 462
A14: E001 | B14: 00000493 | C14: COLABORATIVA S.A.C. | D14: 45939 | E14: 45957.447 | F14: EURO CARS PERU S.A.C. | H14: RUC | I14: 20608892215 | J14: [{'codigo_producto': 2026, 'cantidad': '1', 'valor_unitario': 84.75, 'precio_unitario': 100.01, 'descuento': 0.0, 'subtotal': 84.75, 'porcentaje_de_igv': '18.01', 'igv': 15.260000000000005, 'total': 100.01, 'moneda': '1', 'tipo_de_cambio': 1.0, 'id_tipo_gasto': 5, 'nom_tipo_gasto': 'Otros', 'id_proveedor': 1579, 'id_producto': 30926, 'nom_producto': 'SERVICIO DE MANTENIMIENTO', 'categoria_producto': 'EVENTOS', 'id_estado': 'paid', 'nombre_estado': 'Pagado', 'evento': {'id_evento': '', 'nom_evento': '', 'fecha_hora_ini_event': '', 'fecha_hora_fin_event': '', 'id_organizador': '', 'nom_organizador': '', 'tipo_organizador': ''}, 'id_cuenta': 877, 'nom_cuenta': '6329000 AsesorÃ­a y consultorÃ­a - Otros', 'distribucion_analitica': [[{'codigo': '', 'nom_distribucion': '', 'sub_categoria': '', 'porcentaje': '100.00'}]]}, {'codigo_producto': 2026, 'cantidad': '1', 'valor_unitario': 25.42, 'precio_unitario': 30.0, 'descuento': 0.0, 'subtotal': 25.42, 'porcentaje_de_igv': '18.02', 'igv': 4.579999999999998, 'total': 30.0, 'moneda': '1', 'tipo_de_cambio': 1.0, 'id_tipo_gasto': 2, 'nom_tipo_gasto': 'Servicios', 'id_proveedor': 1579, 'id_producto': 30927, 'nom_producto': 'SERVICIO DE MANTENIMIENTO', 'categoria_producto': 'EVENTOS', 'id_estado': 'paid', 'nombre_estado': 'Pagado', 'evento': {'id_evento': '', 'nom_evento': '', 'fecha_hora_ini_event': '', 'fecha_hora_fin_event': '', 'id_organizador': '', 'nom_organizador': '', 'tipo_organizador': ''}, 'id_cuenta': 877, 'nom_cuenta': '6329000 AsesorÃ­a y consultorÃ­a - Otros', 'distribucion_analitica': [[{'codigo': '', 'nom_distribucion': '', 'sub_categoria': '', 'porcentaje': '100.00'}]]}] | K14: 45939 | Q14: 2026 | R14: 1 | S14: 84.75 | T14: 100.01 | U14: 0 | V14: 84.75 | W14: 18.01 | X14: 15.26 | Y14: 100.01 | Z14: 1 | AA14: 1 | AB14: 5 | AC14: Otros | AD14: 1579 | AE14: 30926 | AF14: SERVICIO DE MANTENIMIENTO | AG14: EVENTOS | AH14: paid | AI14: Pagado | AJ14: 877 | AK14: 6329000 AsesorÃ­a y consultorÃ­a - Otros | AL14: [[{'codigo': '', 'nom_distribucion': '', 'sub_categoria': '', 'porcentaje': '100.00'}]] | AT14: =+CONCATENATE(A14,"-",B14) -> E001-00000493 | AU14: =+IF(Z14=1,V14,IF(Z14=2,V14*AA14)) -> 84.75 | AV14: =+IF(Z14=1,X14,IF(Z14=2,X14*AA14)) -> 15.26 | AW14: =+IF(Z14=1,Y14,IF(Z14=2,Y14*AA14)) -> 100.01
A15: E001 | B15: 00000493 | C15: COLABORATIVA S.A.C. | D15: 45939 | E15: 45957.447 | F15: EURO CARS PERU S.A.C. | H15: RUC | I15: 20608892215 | J15: [{'codigo_producto': 2026, 'cantidad': '1', 'valor_unitario': 84.75, 'precio_unitario': 100.01, 'descuento': 0.0, 'subtotal': 84.75, 'porcentaje_de_igv': '18.01', 'igv': 15.260000000000005, 'total': 100.01, 'moneda': '1', 'tipo_de_cambio': 1.0, 'id_tipo_gasto': 5, 'nom_tipo_gasto': 'Otros', 'id_proveedor': 1579, 'id_producto': 30926, 'nom_producto': 'SERVICIO DE MANTENIMIENTO', 'categoria_producto': 'EVENTOS', 'id_estado': 'paid', 'nombre_estado': 'Pagado', 'evento': {'id_evento': '', 'nom_evento': '', 'fecha_hora_ini_event': '', 'fecha_hora_fin_event': '', 'id_organizador': '', 'nom_organizador': '', 'tipo_organizador': ''}, 'id_cuenta': 877, 'nom_cuenta': '6329000 AsesorÃ­a y consultorÃ­a - Otros', 'distribucion_analitica': [[{'codigo': '', 'nom_distribucion': '', 'sub_categoria': '', 'porcentaje': '100.00'}]]}, {'codigo_producto': 2026, 'cantidad': '1', 'valor_unitario': 25.42, 'precio_unitario': 30.0, 'descuento': 0.0, 'subtotal': 25.42, 'porcentaje_de_igv': '18.02', 'igv': 4.579999999999998, 'total': 30.0, 'moneda': '1', 'tipo_de_cambio': 1.0, 'id_tipo_gasto': 2, 'nom_tipo_gasto': 'Servicios', 'id_proveedor': 1579, 'id_producto': 30927, 'nom_producto': 'SERVICIO DE MANTENIMIENTO', 'categoria_producto': 'EVENTOS', 'id_estado': 'paid', 'nombre_estado': 'Pagado', 'evento': {'id_evento': '', 'nom_evento': '', 'fecha_hora_ini_event': '', 'fecha_hora_fin_event': '', 'id_organizador': '', 'nom_organizador': '', 'tipo_organizador': ''}, 'id_cuenta': 877, 'nom_cuenta': '6329000 AsesorÃ­a y consultorÃ­a - Otros', 'distribucion_analitica': [[{'codigo': '', 'nom_distribucion': '', 'sub_categoria': '', 'porcentaje': '100.00'}]]}] | K15: 45939 | Q15: 2026 | R15: 1 | S15: 25.42 | T15: 30 | U15: 0 | V15: 25.42 | W15: 18.02 | X15: 4.58 | Y15: 30 | Z15: 1 | AA15: 1 | AB15: 2 | AC15: Servicios | AD15: 1579 | AE15: 30927 | AF15: SERVICIO DE MANTENIMIENTO | AG15: EVENTOS | AH15: paid | AI15: Pagado | AJ15: 877 | AK15: 6329000 AsesorÃ­a y consultorÃ­a - Otros | AL15: [[{'codigo': '', 'nom_distribucion': '', 'sub_categoria': '', 'porcentaje': '100.00'}]] | AT15: =+CONCATENATE(A15,"-",B15) -> E001-00000493 | AU15: =+IF(Z15=1,V15,IF(Z15=2,V15*AA15)) -> 25.42 | AV15: =+IF(Z15=1,X15,IF(Z15=2,X15*AA15)) -> 4.58 | AW15: =+IF(Z15=1,Y15,IF(Z15=2,Y15*AA15)) -> 30
